<?xml version="1.0" encoding="utf-8"?>
<!-- This URDF was automatically created by SolidWorks to URDF Exporter! Originally created by Stephen Brawner (brawner@gmail.com) 
     Commit Version: 1.6.0-4-g7f85cfe  Build Version: 1.6.7995.38578
     For more information, please see http://wiki.ros.org/sw_urdf_exporter -->
<robot
  name="Spider_Assembly_fineMesh_frictionDamp">
  <link
    name="base">
    <inertial>
      <origin
        xyz="-1.2244E-08 1.2927E-08 -0.021795"
        rpy="0 0 0" />
      <mass
        value="1.5" />
      <inertia
        ixx="0.002302"
        ixy="-4.563E-10"
        ixz="-1.0633E-10"
        iyy="0.002302"
        iyz="3.0883E-10"
        izz="0.0042233" />
    </inertial>
    <visual>
      <origin
        xyz="0 0 0"
        rpy="0 0 0" />
      <geometry>
        <mesh
          filename="package://Spider_Assembly_fineMesh_frictionDamp/meshes/base.STL" />
      </geometry>
      <material
        name="">
        <color
          rgba="0.79216 0.81961 0.93333 1" />
      </material>
    </visual>
    <collision>
      <origin
        xyz="0 0 0"
        rpy="0 0 0" />
      <geometry>
        <mesh
          filename="package://Spider_Assembly_fineMesh_frictionDamp/meshes/base.STL" />
      </geometry>
    </collision>
  </link>
  <link
    name="coxa1">
    <inertial>
      <origin
        xyz="0.00066313 0.03521 -0.033151"
        rpy="0 0 0" />
      <mass
        value="0.18" />
      <inertia
        ixx="9.5472E-05"
        ixy="-1.9634E-06"
        ixz="8.7252E-07"
        iyy="4.9485E-05"
        iyz="2.1567E-05"
        izz="9.9667E-05" />
    </inertial>
    <visual>
      <origin
        xyz="0 0 0"
        rpy="0 0 0" />
      <geometry>
        <mesh
          filename="package://Spider_Assembly_fineMesh_frictionDamp/meshes/coxa1.STL" />
      </geometry>
      <material
        name="">
        <color
          rgba="0.79216 0.81961 0.93333 1" />
      </material>
    </visual>
    <collision>
      <origin
        xyz="0 0 0"
        rpy="0 0 0" />
      <geometry>
        <mesh
          filename="package://Spider_Assembly_fineMesh_frictionDamp/meshes/coxa1.STL" />
      </geometry>
    </collision>
  </link>
  <joint
    name="base_to_coxa1"
    type="revolute">
    <origin
      xyz="0 0.1 -0.0229"
      rpy="0 0 0" />
    <parent
      link="base" />
    <child
      link="coxa1" />
    <axis
      xyz="0 0 1" />
    <limit
      lower="-1.0472"
      upper="1.0472"
      effort="10"
      velocity="10" />
    <dynamics
      damping="0.05"
      friction="0.25" />
  </joint>
  <link
    name="femur1">
    <inertial>
      <origin
        xyz="-0.0009176 -0.049861 -0.0049066"
        rpy="0 0 0" />
      <mass
        value="0.07" />
      <inertia
        ixx="8.6552E-05"
        ixy="-1.0528E-08"
        ixz="2.4849E-07"
        iyy="4.8375E-05"
        iyz="-2.6157E-06"
        izz="0.00012439" />
    </inertial>
    <visual>
      <origin
        xyz="0 0 0"
        rpy="0 0 0" />
      <geometry>
        <mesh
          filename="package://Spider_Assembly_fineMesh_frictionDamp/meshes/femur1.STL" />
      </geometry>
      <material
        name="">
        <color
          rgba="1 0.67059 0 1" />
      </material>
    </visual>
    <collision>
      <origin
        xyz="0 0 0"
        rpy="0 0 0" />
      <geometry>
        <mesh
          filename="package://Spider_Assembly_fineMesh_frictionDamp/meshes/femur1.STL" />
      </geometry>
    </collision>
  </link>
  <joint
    name="coxa1_to_femur1"
    type="revolute">
    <origin
      xyz="0.00095743 0.076318 -0.055226"
      rpy="0 0 3.129" />
    <parent
      link="coxa1" />
    <child
      link="femur1" />
    <axis
      xyz="1 0 0" />
    <limit
      lower="-1.5708"
      upper="2.0944"
      effort="10"
      velocity="10" />
    <dynamics
      damping="0.05"
      friction="0.25" />
  </joint>
  <link
    name="tibia1">
    <inertial>
      <origin
        xyz="0.00042461 -0.013369 -0.034865"
        rpy="0 0 0" />
      <mass
        value="0.11" />
      <inertia
        ixx="0.00014528"
        ixy="3.0075E-09"
        ixz="-2.855E-06"
        iyy="0.00014943"
        iyz="-1.5895E-05"
        izz="3.0404E-05" />
    </inertial>
    <visual>
      <origin
        xyz="0 0 0"
        rpy="0 0 0" />
      <geometry>
        <mesh
          filename="package://Spider_Assembly_fineMesh_frictionDamp/meshes/tibia1.STL" />
      </geometry>
      <material
        name="">
        <color
          rgba="0.79216 0.81961 0.93333 1" />
      </material>
    </visual>
    <collision>
      <origin
        xyz="0 0 0"
        rpy="0 0 0" />
      <geometry>
        <mesh
          filename="package://Spider_Assembly_fineMesh_frictionDamp/meshes/tibia1.STL" />
      </geometry>
    </collision>
  </link>
  <joint
    name="femur1_to_tibia1"
    type="revolute">
    <origin
      xyz="0 -0.099941 -0.0034349"
      rpy="0 0 0" />
    <parent
      link="femur1" />
    <child
      link="tibia1" />
    <axis
      xyz="1 0 0" />
    <limit
      lower="-2.0944"
      upper="1.0472"
      effort="10"
      velocity="10" />
    <dynamics
      damping="0.05"
      friction="0.25" />
  </joint>
  <link
    name="coxa2">
    <inertial>
      <origin
        xyz="-0.029531 0.019185 -0.033151"
        rpy="0 0 0" />
      <mass
        value="0.18" />
      <inertia
        ixx="6.4112E-05"
        ixy="2.1508E-05"
        ixz="-1.7843E-05"
        iyy="8.0846E-05"
        iyz="1.2147E-05"
        izz="9.9669E-05" />
    </inertial>
    <visual>
      <origin
        xyz="0 0 0"
        rpy="0 0 0" />
      <geometry>
        <mesh
          filename="package://Spider_Assembly_fineMesh_frictionDamp/meshes/coxa2.STL" />
      </geometry>
      <material
        name="">
        <color
          rgba="0.79216 0.81961 0.93333 1" />
      </material>
    </visual>
    <collision>
      <origin
        xyz="0 0 0"
        rpy="0 0 0" />
      <geometry>
        <mesh
          filename="package://Spider_Assembly_fineMesh_frictionDamp/meshes/coxa2.STL" />
      </geometry>
    </collision>
  </link>
  <joint
    name="base_to_coxa2"
    type="revolute">
    <origin
      xyz="-0.086603 0.050001 -0.0229"
      rpy="0 0 0" />
    <parent
      link="base" />
    <child
      link="coxa2" />
    <axis
      xyz="0 0 1" />
    <limit
      lower="-1.0472"
      upper="1.0472"
      effort="10"
      velocity="10" />
    <dynamics
      damping="0.05"
      friction="0.25" />
  </joint>
  <link
    name="femur2">
    <inertial>
      <origin
        xyz="-0.0009176 -0.049861 -0.0049067"
        rpy="0 0 0" />
      <mass
        value="0.07" />
      <inertia
        ixx="8.6552E-05"
        ixy="-1.0306E-08"
        ixz="2.485E-07"
        iyy="4.8375E-05"
        iyz="-2.6157E-06"
        izz="0.00012439" />
    </inertial>
    <visual>
      <origin
        xyz="0 0 0"
        rpy="0 0 0" />
      <geometry>
        <mesh
          filename="package://Spider_Assembly_fineMesh_frictionDamp/meshes/femur2.STL" />
      </geometry>
      <material
        name="">
        <color
          rgba="1 0.67059 0 1" />
      </material>
    </visual>
    <collision>
      <origin
        xyz="0 0 0"
        rpy="0 0 0" />
      <geometry>
        <mesh
          filename="package://Spider_Assembly_fineMesh_frictionDamp/meshes/femur2.STL" />
      </geometry>
    </collision>
  </link>
  <joint
    name="coxa2_to_femur2"
    type="revolute">
    <origin
      xyz="-0.064264 0.041176 -0.055226"
      rpy="0 0 -2.1406" />
    <parent
      link="coxa2" />
    <child
      link="femur2" />
    <axis
      xyz="1 0 0" />
    <limit
      lower="-1.5708"
      upper="2.0944"
      effort="10"
      velocity="10" />
    <dynamics
      damping="0.05"
      friction="0.25" />
  </joint>
  <link
    name="tibia2">
    <inertial>
      <origin
        xyz="0.00042461 -0.013369 -0.034865"
        rpy="0 0 0" />
      <mass
        value="0.11" />
      <inertia
        ixx="0.00014528"
        ixy="3.2722E-09"
        ixz="-2.856E-06"
        iyy="0.00014944"
        iyz="-1.5895E-05"
        izz="3.0403E-05" />
    </inertial>
    <visual>
      <origin
        xyz="0 0 0"
        rpy="0 0 0" />
      <geometry>
        <mesh
          filename="package://Spider_Assembly_fineMesh_frictionDamp/meshes/tibia2.STL" />
      </geometry>
      <material
        name="">
        <color
          rgba="0.79216 0.81961 0.93333 1" />
      </material>
    </visual>
    <collision>
      <origin
        xyz="0 0 0"
        rpy="0 0 0" />
      <geometry>
        <mesh
          filename="package://Spider_Assembly_fineMesh_frictionDamp/meshes/tibia2.STL" />
      </geometry>
    </collision>
  </link>
  <joint
    name="femur2_to_tibia2"
    type="revolute">
    <origin
      xyz="0 -0.099941 -0.0034349"
      rpy="0 0 0" />
    <parent
      link="femur2" />
    <child
      link="tibia2" />
    <axis
      xyz="1 0 0" />
    <limit
      lower="-2.0944"
      upper="1.0472"
      effort="10"
      velocity="10" />
    <dynamics
      damping="0.05"
      friction="0.25" />
  </joint>
  <link
    name="coxa3">
    <inertial>
      <origin
        xyz="-0.029972 -0.01849 -0.033151"
        rpy="0 0 0" />
      <mass
        value="0.18" />
      <inertia
        ixx="6.116E-05"
        ixy="-2.011E-05"
        ixz="-1.8614E-05"
        iyy="8.3807E-05"
        iyz="-1.0935E-05"
        izz="9.9672E-05" />
    </inertial>
    <visual>
      <origin
        xyz="0 0 0"
        rpy="0 0 0" />
      <geometry>
        <mesh
          filename="package://Spider_Assembly_fineMesh_frictionDamp/meshes/coxa3.STL" />
      </geometry>
      <material
        name="">
        <color
          rgba="0.79216 0.81961 0.93333 1" />
      </material>
    </visual>
    <collision>
      <origin
        xyz="0 0 0"
        rpy="0 0 0" />
      <geometry>
        <mesh
          filename="package://Spider_Assembly_fineMesh_frictionDamp/meshes/coxa3.STL" />
      </geometry>
    </collision>
  </link>
  <joint
    name="base_to_coxa3"
    type="revolute">
    <origin
      xyz="-0.086604 -0.049999 -0.0229"
      rpy="0 0 0" />
    <parent
      link="base" />
    <child
      link="coxa3" />
    <axis
      xyz="0 0 1" />
    <limit
      lower="-1.0472"
      upper="1.0472"
      effort="10"
      velocity="10" />
    <dynamics
      damping="0.05"
      friction="0.25" />
  </joint>
  <link
    name="femur3">
    <inertial>
      <origin
        xyz="-0.00091762 -0.049861 -0.0049049"
        rpy="0 0 0" />
      <mass
        value="0.07" />
      <inertia
        ixx="8.6552E-05"
        ixy="-1.0422E-08"
        ixz="2.4858E-07"
        iyy="4.8375E-05"
        iyz="-2.6155E-06"
        izz="0.00012439" />
    </inertial>
    <visual>
      <origin
        xyz="0 0 0"
        rpy="0 0 0" />
      <geometry>
        <mesh
          filename="package://Spider_Assembly_fineMesh_frictionDamp/meshes/femur3.STL" />
      </geometry>
      <material
        name="">
        <color
          rgba="1 0.67059 0 1" />
      </material>
    </visual>
    <collision>
      <origin
        xyz="0 0 0"
        rpy="0 0 0" />
      <geometry>
        <mesh
          filename="package://Spider_Assembly_fineMesh_frictionDamp/meshes/femur3.STL" />
      </geometry>
    </collision>
  </link>
  <joint
    name="coxa3_to_femur3"
    type="revolute">
    <origin
      xyz="-0.064704 -0.04048 -0.055226"
      rpy="0 0 -1.0118" />
    <parent
      link="coxa3" />
    <child
      link="femur3" />
    <axis
      xyz="1 0 0" />
    <limit
      lower="-1.5708"
      upper="2.0944"
      effort="10"
      velocity="10" />
    <dynamics
      damping="0.05"
      friction="0.25" />
  </joint>
  <link
    name="tibia3">
    <inertial>
      <origin
        xyz="0.0004246 -0.013369 -0.034865"
        rpy="0 0 0" />
      <mass
        value="0.11" />
      <inertia
        ixx="0.00014528"
        ixy="2.9252E-09"
        ixz="-2.8551E-06"
        iyy="0.00014943"
        iyz="-1.5895E-05"
        izz="3.0403E-05" />
    </inertial>
    <visual>
      <origin
        xyz="0 0 0"
        rpy="0 0 0" />
      <geometry>
        <mesh
          filename="package://Spider_Assembly_fineMesh_frictionDamp/meshes/tibia3.STL" />
      </geometry>
      <material
        name="">
        <color
          rgba="0.79216 0.81961 0.93333 1" />
      </material>
    </visual>
    <collision>
      <origin
        xyz="0 0 0"
        rpy="0 0 0" />
      <geometry>
        <mesh
          filename="package://Spider_Assembly_fineMesh_frictionDamp/meshes/tibia3.STL" />
      </geometry>
    </collision>
  </link>
  <joint
    name="femur3_to_tibia3"
    type="revolute">
    <origin
      xyz="0 -0.099941 -0.0034349"
      rpy="0 0 0" />
    <parent
      link="femur3" />
    <child
      link="tibia3" />
    <axis
      xyz="1 0 0" />
    <limit
      lower="-2.0944"
      upper="1.0472"
      effort="10"
      velocity="10" />
    <dynamics
      damping="0.05"
      friction="0.25" />
  </joint>
  <link
    name="coxa4">
    <inertial>
      <origin
        xyz="0.00088599 -0.035205 -0.033151"
        rpy="0 0 0" />
      <mass
        value="0.18" />
      <inertia
        ixx="9.5561E-05"
        ixy="6.7233E-08"
        ixz="7.8148E-08"
        iyy="4.9405E-05"
        iyz="-2.1588E-05"
        izz="9.967E-05" />
    </inertial>
    <visual>
      <origin
        xyz="0 0 0"
        rpy="0 0 0" />
      <geometry>
        <mesh
          filename="package://Spider_Assembly_fineMesh_frictionDamp/meshes/coxa4.STL" />
      </geometry>
      <material
        name="">
        <color
          rgba="0.79216 0.81961 0.93333 1" />
      </material>
    </visual>
    <collision>
      <origin
        xyz="0 0 0"
        rpy="0 0 0" />
      <geometry>
        <mesh
          filename="package://Spider_Assembly_fineMesh_frictionDamp/meshes/coxa4.STL" />
      </geometry>
    </collision>
  </link>
  <joint
    name="base_to_coxa4"
    type="revolute">
    <origin
      xyz="0 -0.1 -0.0229"
      rpy="0 0 0" />
    <parent
      link="base" />
    <child
      link="coxa4" />
    <axis
      xyz="0 0 1" />
    <limit
      lower="-1.0472"
      upper="1.0472"
      effort="10"
      velocity="10" />
    <dynamics
      damping="0.05"
      friction="0.25" />
  </joint>
  <link
    name="femur4">
    <inertial>
      <origin
        xyz="0.00065147 -0.049865 -0.0049066"
        rpy="0 0 0" />
      <mass
        value="0.07" />
      <inertia
        ixx="8.6515E-05"
        ixy="1.1915E-06"
        ixz="3.3076E-07"
        iyy="4.8412E-05"
        iyz="-2.6066E-06"
        izz="0.00012439" />
    </inertial>
    <visual>
      <origin
        xyz="0 0 0"
        rpy="0 0 0" />
      <geometry>
        <mesh
          filename="package://Spider_Assembly_fineMesh_frictionDamp/meshes/femur4.STL" />
      </geometry>
      <material
        name="">
        <color
          rgba="1 0.67059 0 1" />
      </material>
    </visual>
    <collision>
      <origin
        xyz="0 0 0"
        rpy="0 0 0" />
      <geometry>
        <mesh
          filename="package://Spider_Assembly_fineMesh_frictionDamp/meshes/femur4.STL" />
      </geometry>
    </collision>
  </link>
  <joint
    name="coxa4_to_femur4"
    type="revolute">
    <origin
      xyz="0.0024042 -0.076286 -0.055226"
      rpy="0 0 0" />
    <parent
      link="coxa4" />
    <child
      link="femur4" />
    <axis
      xyz="0.9995 0.0315 0" />
    <limit
      lower="-1.5708"
      upper="2.0944"
      effort="10"
      velocity="10" />
    <dynamics
      damping="0.05"
      friction="0.25" />
  </joint>
  <link
    name="tibia4">
    <inertial>
      <origin
        xyz="0.00042261 -0.013369 -0.034865"
        rpy="0 0 0" />
      <mass
        value="0.11" />
      <inertia
        ixx="0.00014528"
        ixy="3.0099E-09"
        ixz="-2.855E-06"
        iyy="0.00014943"
        iyz="-1.5895E-05"
        izz="3.0404E-05" />
    </inertial>
    <visual>
      <origin
        xyz="0 0 0"
        rpy="0 0 0" />
      <geometry>
        <mesh
          filename="package://Spider_Assembly_fineMesh_frictionDamp/meshes/tibia4.STL" />
      </geometry>
      <material
        name="">
        <color
          rgba="0.79216 0.81961 0.93333 1" />
      </material>
    </visual>
    <collision>
      <origin
        xyz="0 0 0"
        rpy="0 0 0" />
      <geometry>
        <mesh
          filename="package://Spider_Assembly_fineMesh_frictionDamp/meshes/tibia4.STL" />
      </geometry>
    </collision>
  </link>
  <joint
    name="femur4_to_tibia4"
    type="revolute">
    <origin
      xyz="0.0031481 -0.099891 -0.0034349"
      rpy="0 0 0.031505" />
    <parent
      link="femur4" />
    <child
      link="tibia4" />
    <axis
      xyz="1 0 0" />
    <limit
      lower="-2.0944"
      upper="1.0472"
      effort="10"
      velocity="10" />
    <dynamics
      damping="0.05"
      friction="0.25" />
  </joint>
  <link
    name="coxa5">
    <inertial>
      <origin
        xyz="0.030128 -0.018234 -0.033151"
        rpy="0 0 0" />
      <mass
        value="0.18" />
      <inertia
        ixx="6.276E-05"
        ixy="2.0931E-05"
        ixz="1.8221E-05"
        iyy="8.2199E-05"
        iyz="-1.1573E-05"
        izz="9.9669E-05" />
    </inertial>
    <visual>
      <origin
        xyz="0 0 0"
        rpy="0 0 0" />
      <geometry>
        <mesh
          filename="package://Spider_Assembly_fineMesh_frictionDamp/meshes/coxa5.STL" />
      </geometry>
      <material
        name="">
        <color
          rgba="0.79216 0.81961 0.93333 1" />
      </material>
    </visual>
    <collision>
      <origin
        xyz="0 0 0"
        rpy="0 0 0" />
      <geometry>
        <mesh
          filename="package://Spider_Assembly_fineMesh_frictionDamp/meshes/coxa5.STL" />
      </geometry>
    </collision>
  </link>
  <joint
    name="base_to_coxa5"
    type="revolute">
    <origin
      xyz="0.086601 -0.050001 -0.0229"
      rpy="0 0 0" />
    <parent
      link="base" />
    <child
      link="coxa5" />
    <axis
      xyz="0 0 1" />
    <limit
      lower="-1.0472"
      upper="1.0472"
      effort="10"
      velocity="10" />
    <dynamics
      damping="0.05"
      friction="0.25" />
  </joint>
  <link
    name="femur5">
    <inertial>
      <origin
        xyz="-0.0009176 -0.049861 -0.0049067"
        rpy="0 0 0" />
      <mass
        value="0.07" />
      <inertia
        ixx="8.6552E-05"
        ixy="-1.0306E-08"
        ixz="2.485E-07"
        iyy="4.8375E-05"
        iyz="-2.6157E-06"
        izz="0.00012439" />
    </inertial>
    <visual>
      <origin
        xyz="0 0 0"
        rpy="0 0 0" />
      <geometry>
        <mesh
          filename="package://Spider_Assembly_fineMesh_frictionDamp/meshes/femur5.STL" />
      </geometry>
      <material
        name="">
        <color
          rgba="1 0.67059 0 1" />
      </material>
    </visual>
    <collision>
      <origin
        xyz="0 0 0"
        rpy="0 0 0" />
      <geometry>
        <mesh
          filename="package://Spider_Assembly_fineMesh_frictionDamp/meshes/femur5.STL" />
      </geometry>
    </collision>
  </link>
  <joint
    name="coxa5_to_femur5"
    type="revolute">
    <origin
      xyz="0.065543 -0.039107 -0.055226"
      rpy="0 0 1.0328" />
    <parent
      link="coxa5" />
    <child
      link="femur5" />
    <axis
      xyz="1 0 0" />
    <limit
      lower="-1.5708"
      upper="2.0944"
      effort="10"
      velocity="10" />
    <dynamics
      damping="0.05"
      friction="0.25" />
  </joint>
  <link
    name="tibia5">
    <inertial>
      <origin
        xyz="0.00042461 -0.013369 -0.034865"
        rpy="0 0 0" />
      <mass
        value="0.11" />
      <inertia
        ixx="0.00014528"
        ixy="3.2734E-09"
        ixz="-2.856E-06"
        iyy="0.00014944"
        iyz="-1.5895E-05"
        izz="3.0403E-05" />
    </inertial>
    <visual>
      <origin
        xyz="0 0 0"
        rpy="0 0 0" />
      <geometry>
        <mesh
          filename="package://Spider_Assembly_fineMesh_frictionDamp/meshes/tibia5.STL" />
      </geometry>
      <material
        name="">
        <color
          rgba="0.79216 0.81961 0.93333 1" />
      </material>
    </visual>
    <collision>
      <origin
        xyz="0 0 0"
        rpy="0 0 0" />
      <geometry>
        <mesh
          filename="package://Spider_Assembly_fineMesh_frictionDamp/meshes/tibia5.STL" />
      </geometry>
    </collision>
  </link>
  <joint
    name="femur5_to_tibia5"
    type="revolute">
    <origin
      xyz="0 -0.099941 -0.0034349"
      rpy="0 0 0" />
    <parent
      link="femur5" />
    <child
      link="tibia5" />
    <axis
      xyz="1 0 0" />
    <limit
      lower="-2.0944"
      upper="1.0472"
      effort="10"
      velocity="10" />
    <dynamics
      damping="0.05"
      friction="0.25" />
  </joint>
  <link
    name="coxa6">
    <inertial>
      <origin
        xyz="0.029393 0.019396 -0.033151"
        rpy="0 0 0" />
      <mass
        value="0.18" />
      <inertia
        ixx="6.2409E-05"
        ixy="-2.0764E-05"
        ixz="1.8271E-05"
        iyy="8.2559E-05"
        iyz="1.1498E-05"
        izz="9.9672E-05" />
    </inertial>
    <visual>
      <origin
        xyz="0 0 0"
        rpy="0 0 0" />
      <geometry>
        <mesh
          filename="package://Spider_Assembly_fineMesh_frictionDamp/meshes/coxa6.STL" />
      </geometry>
      <material
        name="">
        <color
          rgba="0.79216 0.81961 0.93333 1" />
      </material>
    </visual>
    <collision>
      <origin
        xyz="0 0 0"
        rpy="0 0 0" />
      <geometry>
        <mesh
          filename="package://Spider_Assembly_fineMesh_frictionDamp/meshes/coxa6.STL" />
      </geometry>
    </collision>
  </link>
  <joint
    name="base_to_coxa6"
    type="revolute">
    <origin
      xyz="0.086602 0.049999 -0.0229"
      rpy="0 0 0" />
    <parent
      link="base" />
    <child
      link="coxa6" />
    <axis
      xyz="0 0 1" />
    <limit
      lower="-1.0472"
      upper="1.0472"
      effort="10"
      velocity="10" />
    <dynamics
      damping="0.05"
      friction="0.25" />
  </joint>
  <link
    name="femur6">
    <inertial>
      <origin
        xyz="-0.00091762 -0.049861 -0.0049049"
        rpy="0 0 0" />
      <mass
        value="0.07" />
      <inertia
        ixx="8.6552E-05"
        ixy="-1.0422E-08"
        ixz="2.4858E-07"
        iyy="4.8375E-05"
        iyz="-2.6155E-06"
        izz="0.00012439" />
    </inertial>
    <visual>
      <origin
        xyz="0 0 0"
        rpy="0 0 0" />
      <geometry>
        <mesh
          filename="package://Spider_Assembly_fineMesh_frictionDamp/meshes/femur6.STL" />
      </geometry>
      <material
        name="">
        <color
          rgba="1 0.67059 0 1" />
      </material>
    </visual>
    <collision>
      <origin
        xyz="0 0 0"
        rpy="0 0 0" />
      <geometry>
        <mesh
          filename="package://Spider_Assembly_fineMesh_frictionDamp/meshes/femur6.STL" />
      </geometry>
    </collision>
  </link>
  <joint
    name="coxa6_to_femur6"
    type="revolute">
    <origin
      xyz="0.063439 0.042436 -0.055226"
      rpy="0 0 2.1604" />
    <parent
      link="coxa6" />
    <child
      link="femur6" />
    <axis
      xyz="1 0 0" />
    <limit
      lower="-1.5708"
      upper="2.0944"
      effort="10"
      velocity="10" />
    <dynamics
      damping="0.05"
      friction="0.25" />
  </joint>
  <link
    name="tibia6">
    <inertial>
      <origin
        xyz="0.0004246 -0.013369 -0.034865"
        rpy="0 0 0" />
      <mass
        value="0.11" />
      <inertia
        ixx="0.00014528"
        ixy="2.9283E-09"
        ixz="-2.8551E-06"
        iyy="0.00014943"
        iyz="-1.5895E-05"
        izz="3.0403E-05" />
    </inertial>
    <visual>
      <origin
        xyz="0 0 0"
        rpy="0 0 0" />
      <geometry>
        <mesh
          filename="package://Spider_Assembly_fineMesh_frictionDamp/meshes/tibia6.STL" />
      </geometry>
      <material
        name="">
        <color
          rgba="0.79216 0.81961 0.93333 1" />
      </material>
    </visual>
    <collision>
      <origin
        xyz="0 0 0"
        rpy="0 0 0" />
      <geometry>
        <mesh
          filename="package://Spider_Assembly_fineMesh_frictionDamp/meshes/tibia6.STL" />
      </geometry>
    </collision>
  </link>
  <joint
    name="femur6_to_tibia6"
    type="revolute">
    <origin
      xyz="0 -0.099941 -0.0034349"
      rpy="0 0 0" />
    <parent
      link="femur6" />
    <child
      link="tibia6" />
    <axis
      xyz="1 0 0" />
    <limit
      lower="-2.0944"
      upper="1.0472"
      effort="10"
      velocity="10" />
    <dynamics
      damping="0.05"
      friction="0.25" />
  </joint>
</robot>